Workbook

Sheet CML Report
S3: Ver: 11.29.2021
B4: Construction Contract Modification Log
B6: General Information: | M6: Legend: | P6: Contract Time Information:
B8: Project Number: | E8: AC-017630 | M8: White cells, project administrator will provide project information (input cells). | P8: Contract Beginning Date: | T8: 44348
B9: Federal Number: | E9: ZP-176(3) | P9: Original Contract Time: | T9: 420
B10: Oracle Number: | E10: F000176030 | M10: Color cells, the excel file will make calculations (formula cells). | P10: Original Termination Date: | T10: =IF(T8>0,(T8+T9-1)," ")
B11: Project Tittle: | E11: Highway Safety Improvements Highway PR-176, km 0.00 to 4.00 San Juan, PR | P11: Total Time Extensions (Days): | T11: =N223
B12: Contractor : | E12: Puerto Rico Asphalt, LLC | M12: Gray cells & Blue Font Color, attention is required (see comment in the cells). | P12: Revised Termination Date: | T12: =IF(T11>0,(T10+T11),T10)
B13: Project Manager: | E13: Ing. Luis R. Pastor Reyes | P13: Change in Contract Time (%): | T13: =IF(T8>0,((T11)/T9),0)
B14: Date: | E14: 45428 | M14: Red Cells, possible action by PRHTA (red flag). | P14: Time Completed to Date (%): | T14: =IF(I16="YES",IF(W14>1,1,W14),W14) | W14: =IF(E14>0,((E14-T8)/(T12-T8)),0)
M15: Red Font Color are for negative numbers or quantities. | P15: Change in Contract Amount (%): | T15: =IF(E225>0,(E225/E62),0)
B16: Has the project reached substantial completion? | H16: Y/N? | I16: NO | P16: % Work Performed to Date: | T16: 0.4
B17: No. of CHO documents: | E17: 4 | P17: Estimated Completion Date: | T17: 44767
B18: No. of EWO documents: | E18: 6 | P18: Administrative Date of Comptroller Office (Contralor): | T18: 45542 | W18: =T18-E14
P19: Project End Date (FMIS): | T19: 45145 | W19: =T19-E14
B22: Project Description: | E22: This project is located on Highway PR-176 from kilometer 0.00 to 4.00 for total length of 4 km. The Pavement Rehabiltation and Safety Improvement Project for PR-176, commences at its intersection with PR-1 and continue along the exixting highway up to the intersection with PR-199 in the municipality of San Juan. The proposed works consist of the improvements to the exixting roadside safety elements at highway PR-176. The works to be performed also include: maintenance and protection of traffic, cold milling and placement of bituminous pavement, the aplication thermoplastic pavement marking, installation of traffic signs, removal, storage and delivered of exixting guard rail, furnishing and installation of Wbeam guard rail single face and double face, contruction of new transition modules traffic signals and other miscellaneous works as shown on plans.
K27: NOTES:
B28: Is this project eligible for toll credits? | H28: Y/N? | I28: YES | K28: 1- Examples of projects that are not eligible for toll credits (answer to the question is NO): ER Projects and Old Projects without Toll Credits.
B29: Does the project have pay items with ER funds? | H29: Y/N? | I29: NO | K29: =IF(I29="NO","",IF(I29="","","2- Reminder: The project manager will develop separate ROAs for CHO or EWO with ER funded pay items from regular federally funded modifications."))
B31: Original Project Funds Information
B32: Units | C32: Federal Share % | E32: INPUT PROJECT AGREEMENT | K32: FEDERAL FUNDS | O32: STATE FUNDS
E33: Participating | G33: Contingencies (Participating) | I33: Payroll, Mileage and Diets | K33: F.A. Funds Requested | L33: Contingencies (Federal Funds) | M33: Calculation of Toll Credits | N33: Contingencies (Toll Credits) | O33: State Share of Federal Funds | P33: Contingencies (State Share) | Q33: Not Participating (State Funds) | R33: Contingencies (Not Participating) | T33: Payroll, Mileage and Diets
B35: Unit 1 | C35: =IF(K35>0,(K35)/(E35+G35+I35),"N/A") | E35: 1937696 | G35: 193769.6 | K35: 1710501.1 | L35: =ROUND(IF(C35="N/A",0,G35*C35),2) | M35: =ROUND(IF($I$28="YES",IF(C35="N/A",0,(E35+G35+I35)*(1-C35)),0),2) | N35: =ROUND(IF($I$28="YES",IF(C35="N/A",0,G35*(1-C35)),0),2) | O35: =ROUND(IF($I$28="NO",IF(C35="N/A",0,(E35+G35+I35)*(1-C35)),0),2) | P35: =ROUND(IF($I$28="NO",IF(C35="N/A",0,G35*(1-C35)),0),2) | Q35: 58670 | R35: 5867
B36: Unit 2 | C36: =IF(K36>0,(K36)/(E36+G36+I36),"N/A") | E36: 44161 | G36: 4416.1 | K36: 48577.1 | L36: =ROUND(IF(C36="N/A",0,G36*C36),2) | M36: =ROUND(IF($I$28="YES",IF(C36="N/A",0,(E36+G36+I36)*(1-C36)),0),2) | N36: =ROUND(IF($I$28="YES",IF(C36="N/A",0,G36*(1-C36)),0),2) | O36: =ROUND(IF($I$28="NO",IF(C36="N/A",0,(E36+G36+I36)*(1-C36)),0),2) | P36: =ROUND(IF($I$28="NO",IF(C36="N/A",0,G36*(1-C36)),0),2) | Q36: 0 | R36: 0
B37: Unit 3 | C37: =IF(K37>0,(K37)/(E37+G37+I37),"N/A") | E37: 218354 | G37: 21835.4 | K37: 240189.4 | L37: =ROUND(IF(C37="N/A",0,G37*C37),2) | M37: =ROUND(IF($I$28="YES",IF(C37="N/A",0,(E37+G37+I37)*(1-C37)),0),2) | N37: =ROUND(IF($I$28="YES",IF(C37="N/A",0,G37*(1-C37)),0),2) | O37: =ROUND(IF($I$28="NO",IF(C37="N/A",0,(E37+G37+I37)*(1-C37)),0),2) | P37: =ROUND(IF($I$28="NO",IF(C37="N/A",0,G37*(1-C37)),0),2) | Q37: 0 | R37: 0
B38: Unit 4 | C38: =IF(K38>0,(K38)/(E38+G38+I38),"N/A") | E38: 858618 | G38: 85861.8 | K38: 757945.03 | L38: =ROUND(IF(C38="N/A",0,G38*C38),2) | M38: =ROUND(IF($I$28="YES",IF(C38="N/A",0,(E38+G38+I38)*(1-C38)),0),2) | N38: =ROUND(IF($I$28="YES",IF(C38="N/A",0,G38*(1-C38)),0),2) | O38: =ROUND(IF($I$28="NO",IF(C38="N/A",0,(E38+G38+I38)*(1-C38)),0),2) | P38: =ROUND(IF($I$28="NO",IF(C38="N/A",0,G38*(1-C38)),0),2) | Q38: 20000 | R38: 2000
B39: Unit 5 | C39: =IF(K39>0,(K39)/(E39+G39+I39),"N/A") | L39: =ROUND(IF(C39="N/A",0,G39*C39),2) | M39: =ROUND(IF($I$28="YES",IF(C39="N/A",0,(E39+G39+I39)*(1-C39)),0),2) | N39: =ROUND(IF($I$28="YES",IF(C39="N/A",0,G39*(1-C39)),0),2) | O39: =ROUND(IF($I$28="NO",IF(C39="N/A",0,(E39+G39+I39)*(1-C39)),0),2) | P39: =ROUND(IF($I$28="NO",IF(C39="N/A",0,G39*(1-C39)),0),2)
B40: Unit 6 | C40: =IF(K40>0,(K40)/(E40+G40+I40),"N/A") | L40: =ROUND(IF(C40="N/A",0,G40*C40),2) | M40: =ROUND(IF($I$28="YES",IF(C40="N/A",0,(E40+G40+I40)*(1-C40)),0),2) | N40: =ROUND(IF($I$28="YES",IF(C40="N/A",0,G40*(1-C40)),0),2) | O40: =ROUND(IF($I$28="NO",IF(C40="N/A",0,(E40+G40+I40)*(1-C40)),0),2) | P40: =ROUND(IF($I$28="NO",IF(C40="N/A",0,G40*(1-C40)),0),2)
B41: Unit 7 | C41: =IF(K41>0,(K41)/(E41+G41+I41),"N/A") | L41: =ROUND(IF(C41="N/A",0,G41*C41),2) | M41: =ROUND(IF($I$28="YES",IF(C41="N/A",0,(E41+G41+I41)*(1-C41)),0),2) | N41: =ROUND(IF($I$28="YES",IF(C41="N/A",0,G41*(1-C41)),0),2) | O41: =ROUND(IF($I$28="NO",IF(C41="N/A",0,(E41+G41+I41)*(1-C41)),0),2) | P41: =ROUND(IF($I$28="NO",IF(C41="N/A",0,G41*(1-C41)),0),2)
B42: Unit 8 | C42: =IF(K42>0,(K42)/(E42+G42+I42),"N/A") | L42: =ROUND(IF(C42="N/A",0,G42*C42),2) | M42: =ROUND(IF($I$28="YES",IF(C42="N/A",0,(E42+G42+I42)*(1-C42)),0),2) | N42: =ROUND(IF($I$28="YES",IF(C42="N/A",0,G42*(1-C42)),0),2) | O42: =ROUND(IF($I$28="NO",IF(C42="N/A",0,(E42+G42+I42)*(1-C42)),0),2) | P42: =ROUND(IF($I$28="NO",IF(C42="N/A",0,G42*(1-C42)),0),2)
B43: Unit 9 | C43: =IF(K43>0,(K43)/(E43+G43+I43),"N/A") | L43: =ROUND(IF(C43="N/A",0,G43*C43),2) | M43: =ROUND(IF($I$28="YES",IF(C43="N/A",0,(E43+G43+I43)*(1-C43)),0),2) | N43: =ROUND(IF($I$28="YES",IF(C43="N/A",0,G43*(1-C43)),0),2) | O43: =ROUND(IF($I$28="NO",IF(C43="N/A",0,(E43+G43+I43)*(1-C43)),0),2) | P43: =ROUND(IF($I$28="NO",IF(C43="N/A",0,G43*(1-C43)),0),2)
B44: Unit 10 | C44: =IF(K44>0,(K44)/(E44+G44+I44),"N/A") | L44: =ROUND(IF(C44="N/A",0,G44*C44),2) | M44: =ROUND(IF($I$28="YES",IF(C44="N/A",0,(E44+G44+I44)*(1-C44)),0),2) | N44: =ROUND(IF($I$28="YES",IF(C44="N/A",0,G44*(1-C44)),0),2) | O44: =ROUND(IF($I$28="NO",IF(C44="N/A",0,(E44+G44+I44)*(1-C44)),0),2) | P44: =ROUND(IF($I$28="NO",IF(C44="N/A",0,G44*(1-C44)),0),2)
B45: Unit 11 | C45: =IF(K45>0,(K45)/(E45+G45+I45),"N/A") | L45: =ROUND(IF(C45="N/A",0,G45*C45),2) | M45: =ROUND(IF($I$28="YES",IF(C45="N/A",0,(E45+G45+I45)*(1-C45)),0),2) | N45: =ROUND(IF($I$28="YES",IF(C45="N/A",0,G45*(1-C45)),0),2) | O45: =ROUND(IF($I$28="NO",IF(C45="N/A",0,(E45+G45+I45)*(1-C45)),0),2) | P45: =ROUND(IF($I$28="NO",IF(C45="N/A",0,G45*(1-C45)),0),2)
B46: Unit 12 | C46: =IF(K46>0,(K46)/(E46+G46+I46),"N/A") | L46: =ROUND(IF(C46="N/A",0,G46*C46),2) | M46: =ROUND(IF($I$28="YES",IF(C46="N/A",0,(E46+G46+I46)*(1-C46)),0),2) | N46: =ROUND(IF($I$28="YES",IF(C46="N/A",0,G46*(1-C46)),0),2) | O46: =ROUND(IF($I$28="NO",IF(C46="N/A",0,(E46+G46+I46)*(1-C46)),0),2) | P46: =ROUND(IF($I$28="NO",IF(C46="N/A",0,G46*(1-C46)),0),2)
B47: Unit 13 | C47: =IF(K47>0,(K47)/(E47+G47+I47),"N/A") | L47: =ROUND(IF(C47="N/A",0,G47*C47),2) | M47: =ROUND(IF($I$28="YES",IF(C47="N/A",0,(E47+G47+I47)*(1-C47)),0),2) | N47: =ROUND(IF($I$28="YES",IF(C47="N/A",0,G47*(1-C47)),0),2) | O47: =ROUND(IF($I$28="NO",IF(C47="N/A",0,(E47+G47+I47)*(1-C47)),0),2) | P47: =ROUND(IF($I$28="NO",IF(C47="N/A",0,G47*(1-C47)),0),2)
B48: Unit 14 | C48: =IF(K48>0,(K48)/(E48+G48+I48),"N/A") | L48: =ROUND(IF(C48="N/A",0,G48*C48),2) | M48: =ROUND(IF($I$28="YES",IF(C48="N/A",0,(E48+G48+I48)*(1-C48)),0),2) | N48: =ROUND(IF($I$28="YES",IF(C48="N/A",0,G48*(1-C48)),0),2) | O48: =ROUND(IF($I$28="NO",IF(C48="N/A",0,(E48+G48+I48)*(1-C48)),0),2) | P48: =ROUND(IF($I$28="NO",IF(C48="N/A",0,G48*(1-C48)),0),2)
B49: Unit 15 | C49: =IF(K49>0,(K49)/(E49+G49+I49),"N/A") | L49: =ROUND(IF(C49="N/A",0,G49*C49),2) | M49: =ROUND(IF($I$28="YES",IF(C49="N/A",0,(E49+G49+I49)*(1-C49)),0),2) | N49: =ROUND(IF($I$28="YES",IF(C49="N/A",0,G49*(1-C49)),0),2) | O49: =ROUND(IF($I$28="NO",IF(C49="N/A",0,(E49+G49+I49)*(1-C49)),0),2) | P49: =ROUND(IF($I$28="NO",IF(C49="N/A",0,G49*(1-C49)),0),2)
B50: Unit 16 | C50: =IF(K50>0,(K50)/(E50+G50+I50),"N/A") | L50: =ROUND(IF(C50="N/A",0,G50*C50),2) | M50: =ROUND(IF($I$28="YES",IF(C50="N/A",0,(E50+G50+I50)*(1-C50)),0),2) | N50: =ROUND(IF($I$28="YES",IF(C50="N/A",0,G50*(1-C50)),0),2) | O50: =ROUND(IF($I$28="NO",IF(C50="N/A",0,(E50+G50+I50)*(1-C50)),0),2) | P50: =ROUND(IF($I$28="NO",IF(C50="N/A",0,G50*(1-C50)),0),2)
... B59: Unit 25 | C59: =IF(K59>0,(K59)/(E59+G59+I59),"N/A") | L59: =ROUND(IF(C59="N/A",0,G59*C59),2) | M59: =ROUND(IF($I$28="YES",IF(C59="N/A",0,(E59+G59+I59)*(1-C59)),0),2) | N59: =ROUND(IF($I$28="YES",IF(C59="N/A",0,G59*(1-C59)),0),2) | O59: =ROUND(IF($I$28="NO",IF(C59="N/A",0,(E59+G59+I59)*(1-C59)),0),2) | P59: =ROUND(IF($I$28="NO",IF(C59="N/A",0,G59*(1-C59)),0),2)
B60: Sub Totals | E60: =SUM(E35:F59) | G60: =SUM(G35:H59) | I60: =SUM(I35:J59) | K60: =SUM(K35:K59) | L60: =SUM(L35:L59) | M60: =SUM(M35:M59) | N60: =SUM(N35:N59) | O60: =SUM(O35:O59) | P60: =SUM(P35:P59) | Q60: =SUM(Q35:Q59) | R60: =SUM(R35:S59) | T60: =SUM(T35:U59)
...

Sheet Data Analysis
A1: Report Date | B1: Project No. | C1: Federal No. | D1: Oracle No. | E1: Project Title | F1: Contractor | G1: Contract Beginning Date | H1: Original Contract Time | I1: Original Termination Date: | J1: Total Time Extensions (Days): | K1: Revised Termination Date: | L1: Change in Contract Time (%): | M1: % of Time Completed to Date: | N1: Change in Contract Amount (%): | O1: % Work Performed to Date: | P1: Estimated Completion Date: | Q1: Project End Date (FMIS): | R1: Eng. Contract Estimate: | S1: Total Construction Cost: | T1: Number of CHO documents: | U1: Number of EWO documents: | V1: Revised Contract Amount: | W1: Obligation Amount: | X1: Amount of Federal Funds Needed (FMIS): | Y1: Amount of State Funds Needed (FMIS):
A2: =IF('CML Report'!E14=0," ",'CML Report'!E14) | B2: =IF('CML Report'!E8=0," ",'CML Report'!E8) | C2: =IF('CML Report'!E9=0," ",'CML Report'!E9) | D2: =IF('CML Report'!E10=0," ",'CML Report'!E10) | E2: =IF('CML Report'!E11=0," ",'CML Report'!E11) | F2: =IF('CML Report'!E12=0," ",'CML Report'!E12) | G2: =IF('CML Report'!T8=0," ",'CML Report'!T8) | H2: =IF('CML Report'!T9=0," ",'CML Report'!T9) | I2: =IF('CML Report'!T10=0," ",'CML Report'!T10) | J2: =IF('CML Report'!T11=0," ",'CML Report'!T11) | K2: =IF('CML Report'!T12=0," ",'CML Report'!T12) | L2: =IF('CML Report'!T13=0,0,'CML Report'!T13) | M2: =IF('CML Report'!T14=0,0,'CML Report'!T14) | N2: =IF('CML Report'!T15=0,0,'CML Report'!T15) | O2: =IF('CML Report'!T16=0,0,'CML Report'!T16) | P2: =IF('CML Report'!T17=0," ",'CML Report'!T17) | Q2: =IF('CML Report'!T19=0," ",'CML Report'!T19) | R2: =IF('CML Report'!E62=0,0,'CML Report'!E62) | S2: =IF('CML Report'!E63=0,0,'CML Report'!E63) | T2: =IF('CML Report'!E17=0,0,'CML Report'!E17) | U2: =IF('CML Report'!E18=0,0,'CML Report'!E18) | V2: =IF('CML Report'!E227=0,0,'CML Report'!E227) | W2: =IF('CML Report'!F385=0,0,'CML Report'!F385) | X2: =IF('CML Report'!E228=0,0,'CML Report'!E228) | Y2: =IF('CML Report'!E229=0,0,'CML Report'!E229)
